<robot
  name="gripper_ur">
  <link
    name="base_link_gripper">
    <inertial>
      <origin
        xyz="8.2799E-10 0.032097 -0.017558"
        rpy="0 0 0" />
      <mass
        value="0.062951" />
      <inertia
        ixx="0"
        ixy="0"
        ixz="0"
        iyy="0"
        iyz="0"
        izz="0" />
    </inertial>
    <visual>
      <origin
        xyz="0 0 0"
        rpy="0 0 0" />
      <geometry>
        <mesh
          filename="package://gripper_ur/meshes/base_link.STL" />
      </geometry>
      <material
        name="">
        <color
          rgba="0.79216 0.81961 0.93333 1" />
      </material>
    </visual>
    <collision>
      <origin
        xyz="0 0 0"
        rpy="0 0 0" />
      <geometry>
        <mesh
          filename="package://gripper_ur/meshes/base_link.STL" />
      </geometry>
    </collision>
  </link>
  <link
    name="base_plate_link">
    <inertial>
      <origin
        xyz="-7.0378E-12 0.0041256 0.0062315"
        rpy="0 0 0" />
      <mass
        value="0.064589" />
      <inertia
        ixx="0"
        ixy="0"
        ixz="0"
        iyy="0"
        iyz="0"
        izz="0" />
    </inertial>
    <visual>
      <origin
        xyz="0 0 0"
        rpy="0 0 0" />
      <geometry>
        <mesh
          filename="package://gripper_ur/meshes/base_plate_link.STL" />
      </geometry>
      <material
        name="">
        <color
          rgba="0.79216 0.81961 0.93333 1" />
      </material>
    </visual>
    <collision>
      <origin
        xyz="0 0 0"
        rpy="0 0 0" />
      <geometry>
        <mesh
          filename="package://gripper_ur/meshes/base_plate_link.STL" />
      </geometry>
    </collision>
  </link>
  <joint
    name="base_plate"
    type="fixed">
    <origin
      xyz="0 0 -0.0325"
      rpy="0 0 0" />
    <parent
      link="base_link_gripper" />
    <child
      link="base_plate_link" />
    <axis
      xyz="0 0 0" />
  </joint>
  <link
    name="joint_left_link">
    <inertial>
      <origin
        xyz="-0.00096719 0.00018393 -0.029739"
        rpy="0 0 0" />
      <mass
        value="0.01181" />
      <inertia
        ixx="0"
        ixy="0"
        ixz="0"
        iyy="0"
        iyz="0"
        izz="0" />
    </inertial>
    <visual>
      <origin
        xyz="0 0 0"
        rpy="0 0 0" />
      <geometry>
        <mesh
          filename="package://gripper_ur/meshes/joint_left_link.STL" />
      </geometry>
      <material
        name="">
        <color
          rgba="0.79216 0.81961 0.93333 1" />
      </material>
    </visual>
    <collision>
      <origin
        xyz="0 0 0"
        rpy="0 0 0" />
      <geometry>
        <mesh
          filename="package://gripper_ur/meshes/joint_left_link.STL" />
      </geometry>
    </collision>
  </link>
  <joint
    name="joint_left"
    type="continuous">
    <origin
      xyz="0.03475 -0.01025 0.015"
      rpy="-1.5708 6.123E-17 1.5708" />
    <parent
      link="base_plate_link" />
    <child
      link="joint_left_link" />
    <axis
      xyz="0 -1 0" />
  </joint>
  <link
    name="finger_left_link">
    <inertial>
      <origin
        xyz="-0.0061859 -4.5161E-05 -0.01391"
        rpy="0 0 0" />
      <mass
        value="0.0081518" />
      <inertia
        ixx="0"
        ixy="0"
        ixz="0"
        iyy="0"
        iyz="0"
        izz="0" />
    </inertial>
    <visual>
      <origin
        xyz="0 0 0"
        rpy="0 0 0" />
      <geometry>
        <mesh
          filename="package://gripper_ur/meshes/finger_left_link.STL" />
      </geometry>
      <material
        name="">
        <color
          rgba="0.79216 0.81961 0.93333 1" />
      </material>
    </visual>
    <collision>
      <origin
        xyz="0 0 0"
        rpy="0 0 0" />
      <geometry>
        <mesh
          filename="package://gripper_ur/meshes/finger_left_link.STL" />
      </geometry>
    </collision>
  </link>
  <joint
    name="Joint_finger_left"
    type="continuous">
    <origin
      xyz="0 0 -0.065"
      rpy="9.3543E-15 -0.47313 -4.2625E-15" />
    <parent
      link="joint_left_link" />
    <child
      link="finger_left_link" />
    <axis
      xyz="0 -1 0" />
  </joint>
  <link
    name="festo_left_link">
    <inertial>
      <origin
        xyz="8.9608E-05 0.025359 -1.6653E-16"
        rpy="0 0 0" />
      <mass
        value="0.01909" />
      <inertia
        ixx="0"
        ixy="0"
        ixz="0"
        iyy="0"
        iyz="0"
        izz="0" />
    </inertial>
    <visual>
      <origin
        xyz="0 0 0"
        rpy="0 0 0" />
      <geometry>
        <mesh
          filename="package://gripper_ur/meshes/festo_left_link.STL" />
      </geometry>
      <material
        name="">
        <color
          rgba="0.79216 0.81961 0.93333 1" />
      </material>
    </visual>
    <collision>
      <origin
        xyz="0 0 0"
        rpy="0 0 0" />
      <geometry>
        <mesh
          filename="package://gripper_ur/meshes/festo_left_link.STL" />
      </geometry>
    </collision>
  </link>
  <joint
    name="joint_festo_left"
    type="fixed">
    <origin
      xyz="-0.0028917 0 -0.0097109"
      rpy="1.5708 0.85495 -3.1416" />
    <parent
      link="finger_left_link" />
    <child
      link="festo_left_link" />
    <axis
      xyz="0 0 0" />
  </joint>
  <link
    name="joint_right_link">
    <inertial>
      <origin
        xyz="0.00049585 0.00018393 -0.02975"
        rpy="0 0 0" />
      <mass
        value="0.01181" />
      <inertia
        ixx="0"
        ixy="0"
        ixz="0"
        iyy="0"
        iyz="0"
        izz="0" />
    </inertial>
    <visual>
      <origin
        xyz="0 0 0"
        rpy="0 0 0" />
      <geometry>
        <mesh
          filename="package://gripper_ur/meshes/joint_right_link.STL" />
      </geometry>
      <material
        name="">
        <color
          rgba="0.79216 0.81961 0.93333 1" />
      </material>
    </visual>
    <collision>
      <origin
        xyz="0 0 0"
        rpy="0 0 0" />
      <geometry>
        <mesh
          filename="package://gripper_ur/meshes/joint_right_link.STL" />
      </geometry>
    </collision>
  </link>
  <joint
    name="joint_right"
    type="continuous">
    <origin
      xyz="-0.03475 -0.01025 0.015"
      rpy="-1.5708 -1.2472E-16 -1.555" />
    <parent
      link="base_plate_link" />
    <child
      link="joint_right_link" />
    <axis
      xyz="0 -1 0" />
  </joint>
  <link
    name="finger_right_link">
    <inertial>
      <origin
        xyz="-0.0052726 4.5161E-05 -0.014386"
        rpy="0 0 0" />
      <mass
        value="0.0081518" />
      <inertia
        ixx="0"
        ixy="0"
        ixz="0"
        iyy="0"
        iyz="0"
        izz="0" />
    </inertial>
    <visual>
      <origin
        xyz="0 0 0"
        rpy="0 0 0" />
      <geometry>
        <mesh
          filename="package://gripper_ur/meshes/finger_right_link.STL" />
      </geometry>
      <material
        name="">
        <color
          rgba="0.79216 0.81961 0.93333 1" />
      </material>
    </visual>
    <collision>
      <origin
        xyz="0 0 0"
        rpy="0 0 0" />
      <geometry>
        <mesh
          filename="package://gripper_ur/meshes/finger_right_link.STL" />
      </geometry>
    </collision>
  </link>
  <joint
    name="joint_finger_right"
    type="continuous">
    <origin
      xyz="0 0 -0.065"
      rpy="-7.8621E-15 -0.48898 -3.1416" />
    <parent
      link="joint_right_link" />
    <child
      link="finger_right_link" />
    <axis
      xyz="0 1 0" />
  </joint>
  <link
    name="festo_right_link">
    <inertial>
      <origin
        xyz="8.9608E-05 0.025359 -3.5388E-16"
        rpy="0 0 0" />
      <mass
        value="0.01909" />
      <inertia
        ixx="0"
        ixy="0"
        ixz="0"
        iyy="0"
        iyz="0"
        izz="0" />
    </inertial>
    <visual>
      <origin
        xyz="0 0 0"
        rpy="0 0 0" />
      <geometry>
        <mesh
          filename="package://gripper_ur/meshes/festo_right_link.STL" />
      </geometry>
      <material
        name="">
        <color
          rgba="0.79216 0.81961 0.93333 1" />
      </material>
    </visual>
    <collision>
      <origin
        xyz="0 0 0"
        rpy="0 0 0" />
      <geometry>
        <mesh
          filename="package://gripper_ur/meshes/festo_right_link.STL" />
      </geometry>
    </collision>
  </link>
  <joint
    name="joint_festo_right"
    type="fixed">
    <origin
      xyz="-0.0019784 0 -0.010187"
      rpy="1.5708 0.85495 -3.1416" />
    <parent
      link="finger_right_link" />
    <child
      link="festo_right_link" />
    <axis
      xyz="0 0 0" />
  </joint>
  <link
    name="base_plate_two_link">
    <inertial>
      <origin
        xyz="1.1632E-07 0.0022711 -0.0027948"
        rpy="0 0 0" />
      <mass
        value="0.10598" />
      <inertia
        ixx="0"
        ixy="0"
        ixz="0"
        iyy="0"
        iyz="0"
        izz="0" />
    </inertial>
    <visual>
      <origin
        xyz="0 0 0"
        rpy="0 0 0" />
      <geometry>
        <mesh
          filename="package://gripper_ur/meshes/base_plate_two_link.STL" />
      </geometry>
      <material
        name="">
        <color
          rgba="0.79216 0.81961 0.93333 1" />
      </material>
    </visual>
    <collision>
      <origin
        xyz="0 0 0"
        rpy="0 0 0" />
      <geometry>
        <mesh
          filename="package://gripper_ur/meshes/base_plate_two_link.STL" />
      </geometry>
    </collision>
  </link>
  <joint
    name="joint_base_plate_two"
    type="fixed">
    <origin
      xyz="0 0 0.0325"
      rpy="3.1416 0 0" />
    <parent
      link="base_plate_link" />
    <child
      link="base_plate_two_link" />
    <axis
      xyz="0 0 0" />
  </joint>
  <link
    name="camera_link">
    <inertial>
      <origin
        xyz="0.00010101 0.0086143 -0.013617"
        rpy="0 0 0" />
      <mass
        value="0.083429" />
      <inertia
        ixx="9.7093E-07"
        ixy="2.7743E-09"
        ixz="1.0334E-11"
        iyy="6.1263E-08"
        iyz="-3.2036E-09"
        izz="1.0322E-06" />
    </inertial>
    <visual>
      <origin
        xyz="0 0 0"
        rpy="0 0 0" />
      <geometry>
        <mesh
          filename="package://gripper_ur/meshes/camera_link.STL" />
      </geometry>
      <material
        name="">
        <color
          rgba="0.79216 0.81961 0.93333 1" />
      </material>
    </visual>
    <collision>
      <origin
        xyz="0 0 0"
        rpy="0 0 0" />
      <geometry>
        <mesh
          filename="package://gripper_ur/meshes/camera_link.STL" />
      </geometry>
    </collision>
  </link>
  <joint
    name="joint_camera"
    type="fixed">
    <origin
      xyz="0 0.034 -0.008"
      rpy="6.123E-17 6.123E-17 -3.1416" />
    <parent
      link="base_plate_two_link" />
    <child
      link="camera_link" />
    <axis
      xyz="0 0 0" />
  </joint>
  <link
    name="servo_right_link">
    <inertial>
      <origin
        xyz="1.9207E-08 0.00028935 -0.019039"
        rpy="0 0 0" />
      <mass
        value="0.029949" />
      <inertia
        ixx="0"
        ixy="0"
        ixz="0"
        iyy="0"
        iyz="0"
        izz="0" />
    </inertial>
    <visual>
      <origin
        xyz="0 0 0"
        rpy="0 0 0" />
      <geometry>
        <mesh
          filename="package://gripper_ur/meshes/servo_right_link.STL" />
      </geometry>
      <material
        name="">
        <color
          rgba="0.79216 0.81961 0.93333 1" />
      </material>
    </visual>
    <collision>
      <origin
        xyz="0 0 0"
        rpy="0 0 0" />
      <geometry>
        <mesh
          filename="package://gripper_ur/meshes/servo_right_link.STL" />
      </geometry>
    </collision>
  </link>
  <joint
    name="joint_servo_right"
    type="fixed">
    <origin
      xyz="-0.03475 0 0.061"
      rpy="1.7384E-16 3.0322E-16 3.1416" />
    <parent
      link="base_plate_link" />
    <child
      link="servo_right_link" />
    <axis
      xyz="0 0 0" />
  </joint>
  <link
    name="servo_left_link">
    <inertial>
      <origin
        xyz="1.9207E-08 0.00028935 -0.019039"
        rpy="0 0 0" />
      <mass
        value="0.029949" />
      <inertia
        ixx="0"
        ixy="0"
        ixz="0"
        iyy="0"
        iyz="0"
        izz="0" />
    </inertial>
    <visual>
      <origin
        xyz="0 0 0"
        rpy="0 0 0" />
      <geometry>
        <mesh
          filename="package://gripper_ur/meshes/servo_left_link.STL" />
      </geometry>
      <material
        name="">
        <color
          rgba="0.79216 0.81961 0.93333 1" />
      </material>
    </visual>
    <collision>
      <origin
        xyz="0 0 0"
        rpy="0 0 0" />
      <geometry>
        <mesh
          filename="package://gripper_ur/meshes/servo_left_link.STL" />
      </geometry>
    </collision>
  </link>
  <joint
    name="joint_servo_lleft"
    type="fixed">
    <origin
      xyz="0.03475 0 0.061"
      rpy="1.7348E-16 6.123E-17 3.1416" />
    <parent
      link="base_plate_link" />
    <child
      link="servo_left_link" />
    <axis
      xyz="0 0 0" />
  </joint>
  <link
    name="finger_two_right_link">
    <inertial>
      <origin
        xyz="-0.0313 0.0081481 3.3286E-05"
        rpy="0 0 0" />
      <mass
        value="0.011213" />
      <inertia
        ixx="0"
        ixy="0"
        ixz="0"
        iyy="0"
        iyz="0"
        izz="0" />
    </inertial>
    <visual>
      <origin
        xyz="0 0 0"
        rpy="0 0 0" />
      <geometry>
        <mesh
          filename="package://gripper_ur/meshes/finger_two_right_link.STL" />
      </geometry>
      <material
        name="">
        <color
          rgba="0.79216 0.81961 0.93333 1" />
      </material>
    </visual>
    <collision>
      <origin
        xyz="0 0 0"
        rpy="0 0 0" />
      <geometry>
        <mesh
          filename="package://gripper_ur/meshes/finger_two_right_link.STL" />
      </geometry>
    </collision>
  </link>
  <joint
    name="joint_finger_two_right"
    type="fixed">
    <origin
      xyz="-0.055 0 0.015"
      rpy="4.5212E-16 3.3777E-16 0.18526" />
    <parent
      link="base_plate_link" />
    <child
      link="finger_two_right_link" />
    <axis
      xyz="0 0 0" />
  </joint>
  <link
    name="finger_two_left_link">
    <inertial>
      <origin
        xyz="0.0081481 -0.031299 3.281E-05"
        rpy="0 0 0" />
      <mass
        value="0.011213" />
      <inertia
        ixx="0"
        ixy="0"
        ixz="0"
        iyy="0"
        iyz="0"
        izz="0" />
    </inertial>
    <visual>
      <origin
        xyz="0 0 0"
        rpy="0 0 0" />
      <geometry>
        <mesh
          filename="package://gripper_ur/meshes/finger_two_left_link.STL" />
      </geometry>
      <material
        name="">
        <color
          rgba="0.79216 0.81961 0.93333 1" />
      </material>
    </visual>
    <collision>
      <origin
        xyz="0 0 0"
        rpy="0 0 0" />
      <geometry>
        <mesh
          filename="package://gripper_ur/meshes/finger_two_left_link.STL" />
      </geometry>
    </collision>
  </link>
  <joint
    name="joint_finger_two_left"
    type="fixed">
    <origin
      xyz="0.055 0 0.015"
      rpy="-9.6748E-17 1.0664E-16 1.3855" />
    <parent
      link="base_plate_link" />
    <child
      link="finger_two_left_link" />
    <axis
      xyz="0 0 0" />
  </joint>
</robot>
